<mujoco>
            
            <default>
                <default class="cup_side">
                    <geom type="box" material="bucket#2:glass" size="0.0025 0.0220 0.0500" pos="0.05 0.0 0.0500" euler="0 0.05 0" />
                </default>
                <default class="cup_bottom">
                    <geom type="box" material="bucket#2:glass" size="0.0220 0.0500 0.0025" />
                </default>
            <default class="visual">
            <geom type="mesh" contype="0" conaffinity="0" group="2" />
        </default>
        <default class="collision">
            <geom type="capsule" group="3" />
            <default class="eef_collision">
                <geom type="cylinder" />
            </default>
        </default>
        <site size="0.001" rgba="0.5 0.5 0.5 0.3" group="4" />

        
        <default class="size3">
            <joint axis="0 1 0" range="-6.28319 6.28319" armature="0.1" damping="200" />
            <position ctrlrange="-6.2831 6.2831" kp="3500" forcerange="-150 150" />
            <default class="size3_limited">
                <joint range="-3.1415 3.1415" />
                <position ctrlrange="-3.1415 3.1415" />
            </default>
        </default>
        <default class="size1">
            <joint axis="0 1 0" range="-6.28319 6.28319" armature="0.1" damping="15" />
            <position ctrlrange="-6.2831 6.2831" kp="3000" forcerange="-28 28" />
        </default>
    <default class="2f85">
      <mesh scale="0.001 0.001 0.001" />
      <general biastype="affine" />

      <joint axis="1 0 0" />
      <default class="driver">
        <joint range="0 0.8" armature="0.005" damping="0.1" solimplimit="0.95 0.99 0.001" solreflimit="0.005 1" />
      </default>
      <default class="follower">
        <joint range="-0.872664 0.872664" pos="0 -0.018 0.0065" solimplimit="0.95 0.99 0.001" solreflimit="0.005 1" />
      </default>
      <default class="spring_link">
        <joint range="-0.29670597283 0.8" stiffness="0.05" springref="2.62" damping="0.00125" />
      </default>
      <default class="coupler">
        <joint range="-1.57 0" solimplimit="0.95 0.99 0.001" solreflimit="0.005 1" />
      </default>

      <default class="2f85:visual">
        <geom type="mesh" contype="0" conaffinity="0" group="2" />
      </default>
      <default class="2f85:collision">
        <geom type="mesh" group="3" />
        <default class="pad_box1">
          <geom mass="0" type="box" pos="0 -0.0026 0.028125" size="0.011 0.004 0.009375" friction="0.7" solimp="0.95 0.99 0.001" solref="0.004 1" priority="1" rgba="0.55 0.55 0.55 1" />
        </default>
        <default class="pad_box2">
          <geom mass="0" type="box" pos="0 -0.0026 0.009375" size="0.011 0.004 0.009375" friction="0.6" solimp="0.95 0.99 0.001" solref="0.004 1" priority="1" rgba="0.45 0.45 0.45 1" />
        </default>
      </default>
    </default>
  </default>
            <compiler angle="radian" autolimits="true" />
 
            <size nconmax="10000" njmax="10000" />
            <visual>
                
                <map znear="0.001" zfar="100" />

            </visual>

            <asset>
                
                <texture name="#1:#1:texplane" type="2d" builtin="checker" rgb1=".2 .3 .4" rgb2=".1 0.15 0.2" width="512" height="512" mark="cross" markrgb=".8 .8 .8" />    
                <material name="#1:#1:matplane" reflectance="0.3" texture="#1:#1:texplane" texrepeat="1 1" texuniform="true" />
            <material name="bucket#2:glass" rgba="1 1 1 0.1" />
                <material name="bucket#2:red" rgba=".8 .2 .1 1" />
                <material name="bucket#2:green" rgba=".2 .8 .1 1" />
            <material name="arm#3:black" specular="0.5" shininess="0.25" rgba="0.033 0.033 0.033 1" />
        <material name="arm#3:jointgray" specular="0.5" shininess="0.25" rgba="0.278 0.278 0.278 1" />
        <material name="arm#3:linkgray" specular="0.5" shininess="0.25" rgba="0.82 0.82 0.82 1" />
        <material name="arm#3:urblue" specular="0.5" shininess="0.25" rgba="0.49 0.678 0.8 1" />

        <mesh name="arm#3:base_0" file="/home/danfergo/Projects/yarok/yarok/comm/components/ur5e/assets/base_0.obj" />
        <mesh name="arm#3:base_1" file="/home/danfergo/Projects/yarok/yarok/comm/components/ur5e/assets/base_1.obj" />
        <mesh name="arm#3:shoulder_0" file="/home/danfergo/Projects/yarok/yarok/comm/components/ur5e/assets/shoulder_0.obj" />
        <mesh name="arm#3:shoulder_1" file="/home/danfergo/Projects/yarok/yarok/comm/components/ur5e/assets/shoulder_1.obj" />
        <mesh name="arm#3:shoulder_2" file="/home/danfergo/Projects/yarok/yarok/comm/components/ur5e/assets/shoulder_2.obj" />
        <mesh name="arm#3:upperarm_0" file="/home/danfergo/Projects/yarok/yarok/comm/components/ur5e/assets/upperarm_0.obj" />
        <mesh name="arm#3:upperarm_1" file="/home/danfergo/Projects/yarok/yarok/comm/components/ur5e/assets/upperarm_1.obj" />
        <mesh name="arm#3:upperarm_2" file="/home/danfergo/Projects/yarok/yarok/comm/components/ur5e/assets/upperarm_2.obj" />
        <mesh name="arm#3:upperarm_3" file="/home/danfergo/Projects/yarok/yarok/comm/components/ur5e/assets/upperarm_3.obj" />
        <mesh name="arm#3:forearm_0" file="/home/danfergo/Projects/yarok/yarok/comm/components/ur5e/assets/forearm_0.obj" />
        <mesh name="arm#3:forearm_1" file="/home/danfergo/Projects/yarok/yarok/comm/components/ur5e/assets/forearm_1.obj" />
        <mesh name="arm#3:forearm_2" file="/home/danfergo/Projects/yarok/yarok/comm/components/ur5e/assets/forearm_2.obj" />
        <mesh name="arm#3:forearm_3" file="/home/danfergo/Projects/yarok/yarok/comm/components/ur5e/assets/forearm_3.obj" />
        <mesh name="arm#3:wrist1_0" file="/home/danfergo/Projects/yarok/yarok/comm/components/ur5e/assets/wrist1_0.obj" />
        <mesh name="arm#3:wrist1_1" file="/home/danfergo/Projects/yarok/yarok/comm/components/ur5e/assets/wrist1_1.obj" />
        <mesh name="arm#3:wrist1_2" file="/home/danfergo/Projects/yarok/yarok/comm/components/ur5e/assets/wrist1_2.obj" />
        <mesh name="arm#3:wrist2_0" file="/home/danfergo/Projects/yarok/yarok/comm/components/ur5e/assets/wrist2_0.obj" />
        <mesh name="arm#3:wrist2_1" file="/home/danfergo/Projects/yarok/yarok/comm/components/ur5e/assets/wrist2_1.obj" />
        <mesh name="arm#3:wrist2_2" file="/home/danfergo/Projects/yarok/yarok/comm/components/ur5e/assets/wrist2_2.obj" />
        <mesh name="arm#3:wrist3" file="/home/danfergo/Projects/yarok/yarok/comm/components/ur5e/assets/wrist3.obj" />
    <material name="gripper#4:metal" rgba="0.58 0.58 0.58 1" />
    <material name="gripper#4:silicone" rgba="0.1882 0.1882 0.1882 1" />
    <material name="gripper#4:gray" rgba="0.4627 0.4627 0.4627 1" />
    <material name="gripper#4:black" rgba="0.149 0.149 0.149 1" />

    <mesh class="2f85" name="gripper#4:base_mount" file="/home/danfergo/Projects/yarok/yarok/comm/components/robotiq_2f85/assets/base_mount.stl" />
    <mesh class="2f85" name="gripper#4:base" file="/home/danfergo/Projects/yarok/yarok/comm/components/robotiq_2f85/assets/base.stl" />
    <mesh class="2f85" name="gripper#4:driver" file="/home/danfergo/Projects/yarok/yarok/comm/components/robotiq_2f85/assets/driver.stl" />
    <mesh class="2f85" name="gripper#4:coupler" file="/home/danfergo/Projects/yarok/yarok/comm/components/robotiq_2f85/assets/coupler.stl" />
    <mesh class="2f85" name="gripper#4:follower" file="/home/danfergo/Projects/yarok/yarok/comm/components/robotiq_2f85/assets/follower.stl" />
    <mesh class="2f85" name="gripper#4:follower_trimmed" file="/home/danfergo/Projects/yarok/yarok/comm/components/robotiq_2f85/assets/follower_trimmed.stl" />
    <mesh class="2f85" name="gripper#4:pad" file="/home/danfergo/Projects/yarok/yarok/comm/components/robotiq_2f85/assets/pad.stl" />
    <mesh class="2f85" name="gripper#4:silicone_pad" file="/home/danfergo/Projects/yarok/yarok/comm/components/robotiq_2f85/assets/silicone_pad.stl" />
    <mesh class="2f85" name="gripper#4:spring_link" file="/home/danfergo/Projects/yarok/yarok/comm/components/robotiq_2f85/assets/spring_link.stl" />
  <mesh name="digit1#5:digit_adapter" file="/home/danfergo/Projects/yarok/yarok/comm/components/digit/assets/stls/digit_adapter.STL" scale="0.001 0.001 0.001" />
        <mesh name="digit1#5:digit_back" file="/home/danfergo/Projects/yarok/yarok/comm/components/digit/assets/stls/digit_back.STL" scale="0.001 0.001 0.001" />
        <mesh name="digit1#5:digit_glass" file="/home/danfergo/Projects/yarok/yarok/comm/components/digit/assets/stls/digit_glass.STL" scale="0.001 0.001 0.003" />
        <mesh name="digit1#5:digit_gel" file="/home/danfergo/Projects/yarok/yarok/comm/components/digit/assets/stls/digit_glass.STL" scale="0.001 0.001 0.0009" />
        <mesh name="digit1#5:digit_gel_cover" file="/home/danfergo/Projects/yarok/yarok/comm/components/digit/assets/stls/digit_gel.STL" scale="0.0012 0.0011 0.001" />
        <mesh name="digit1#5:digit_curve" file="/home/danfergo/Projects/yarok/yarok/comm/components/digit/assets/stls/digit_curve_0_5.STL" scale=".001 .001 .001" />

        <material name="digit1#5:black_resin" rgba="0.1 0.1 0.1 1" />
        <material name="digit1#5:gray_elastomer" rgba="0.8 0.8 0.8 1" />
        <material name="digit1#5:transparent_glass" rgba="0.9 0.95 1 0.7" />


        <material name="digit1#5:silver" specular="1" shininess="0.5" reflectance="1" emission="0.25" rgba="0.82 0.82 0.82 1" />
        <material name="digit1#5:grey" specular="1" shininess="0.5" reflectance="1" emission="0.1" rgba="0.5 0.5 0.5 1" />
        <material name="digit1#5:blue" specular="1" shininess="0.5" reflectance="1" emission="0" rgba="0.678 0.847 0.902 1" />
        <material name="digit1#5:black" specular="1" shininess="0.5" reflectance="1" emission="0" rgba="0.2 0.2 0.2 1" />
        <material name="digit1#5:floor_mat" specular="0" shininess="0.5" reflectance="0" rgba="0.2 0.2 0.2 1" />
        <material name="digit1#5:table_mat" specular="0" shininess="0.5" reflectance="0" rgba="0.93 0.93 0.93 1" />
        <material name="digit1#5:block_mat" specular="0" shininess="0.5" reflectance="0" rgba="0.2 0.2 0.2 1" />
        <material name="digit1#5:puck_mat" specular="0" shininess="0.5" reflectance="0" rgba="0.2 0.2 0.2 1" />
    <mesh name="digit2#6:digit_adapter" file="/home/danfergo/Projects/yarok/yarok/comm/components/digit/assets/stls/digit_adapter.STL" scale="0.001 0.001 0.001" />
        <mesh name="digit2#6:digit_back" file="/home/danfergo/Projects/yarok/yarok/comm/components/digit/assets/stls/digit_back.STL" scale="0.001 0.001 0.001" />
        <mesh name="digit2#6:digit_glass" file="/home/danfergo/Projects/yarok/yarok/comm/components/digit/assets/stls/digit_glass.STL" scale="0.001 0.001 0.003" />
        <mesh name="digit2#6:digit_gel" file="/home/danfergo/Projects/yarok/yarok/comm/components/digit/assets/stls/digit_glass.STL" scale="0.001 0.001 0.0009" />
        <mesh name="digit2#6:digit_gel_cover" file="/home/danfergo/Projects/yarok/yarok/comm/components/digit/assets/stls/digit_gel.STL" scale="0.0012 0.0011 0.001" />
        <mesh name="digit2#6:digit_curve" file="/home/danfergo/Projects/yarok/yarok/comm/components/digit/assets/stls/digit_curve_0_5.STL" scale=".001 .001 .001" />

        <material name="digit2#6:black_resin" rgba="0.1 0.1 0.1 1" />
        <material name="digit2#6:gray_elastomer" rgba="0.8 0.8 0.8 1" />
        <material name="digit2#6:transparent_glass" rgba="0.9 0.95 1 0.7" />


        <material name="digit2#6:silver" specular="1" shininess="0.5" reflectance="1" emission="0.25" rgba="0.82 0.82 0.82 1" />
        <material name="digit2#6:grey" specular="1" shininess="0.5" reflectance="1" emission="0.1" rgba="0.5 0.5 0.5 1" />
        <material name="digit2#6:blue" specular="1" shininess="0.5" reflectance="1" emission="0" rgba="0.678 0.847 0.902 1" />
        <material name="digit2#6:black" specular="1" shininess="0.5" reflectance="1" emission="0" rgba="0.2 0.2 0.2 1" />
        <material name="digit2#6:floor_mat" specular="0" shininess="0.5" reflectance="0" rgba="0.2 0.2 0.2 1" />
        <material name="digit2#6:table_mat" specular="0" shininess="0.5" reflectance="0" rgba="0.93 0.93 0.93 1" />
        <material name="digit2#6:block_mat" specular="0" shininess="0.5" reflectance="0" rgba="0.2 0.2 0.2 1" />
        <material name="digit2#6:puck_mat" specular="0" shininess="0.5" reflectance="0" rgba="0.2 0.2 0.2 1" />
    </asset>

            <worldbody>
                <light directional="true" diffuse="1.0 1.0 1.0" specular="0.1 0.1 0.1" pos="0 0 5.0" dir="0 0 -1" />
                <body name="#1:#1:floor">
                    <geom name="#1:#1:ground" type="plane" size="0 0 1" pos="0 0 0" quat="1 0 0 0" material="#1:#1:matplane" />
                </body>
            <body name="#1:base-table" pos="-0.135 -0.48 0.016">
                    <geom type="box" size="0.2 0.2 0.13" />
                </body>
    
                <body pos="-0.135 -0.52 0.21500000000000002">
                        <body zaxis="1 1 1">
                            <composite type="particle" count="4 4 4" spacing="0.0125">
                                <geom size="0.008" material="bucket#2:red" />
                            </composite>
                        </body>
                    </body>   
                    
                    <body pos="-0.135 -0.52 0.265">
                 
                        <body>
                            <composite type="particle" count="4 4 4" spacing="0.02">
                                <geom size="0.008" material="bucket#2:green" mass="0.0001" />
                            </composite>
                        </body>
                    </body>               
                 
    
                 <body pos="-0.135 -0.52 0.165">
                        <freejoint /> 
                        <body euler="0 0 0.0">
                            <geom class="cup_side" />
                        </body>
                        <body euler="0 0 0.78539816339">
                            <geom class="cup_side" />
                        </body> 
                        <body euler="0 0 1.57079632679">
                            <geom class="cup_side" />
                        </body> 
                        <body euler="0 0 2.35619449019">
                            <geom class="cup_side" />
                        </body> 
                        <body euler="0 0 3.14159265359">
                            <geom class="cup_side" />
                        </body> 
                        <body euler="0 0 0.78539816339">
                            <geom class="cup_side" />
                        </body> 
                        <body euler="0 0 3.92699081699">
                            <geom class="cup_side" />
                        </body> 
                        <body euler="0 0 4.71238898038">
                            <geom class="cup_side" />
                        </body> 
                        <body euler="0 0 5.49778714378">
                            <geom class="cup_side" />
                        </body> 
                        
                        <body>
                            <geom class="cup_bottom" euler="0 0 -0.78539816339" />
                            <geom class="cup_bottom" euler="0 0 0" />
                            <geom class="cup_bottom" euler="0 0 0.78539816339" />
                            <geom class="cup_bottom" euler="0 0 1.57079632679" />
                        </body> 
                    </body>
            <body name="arm#3:base" quat="1 0 0 1">
            <inertial mass="4.0" pos="0 0 0" diaginertia="0.00443333156 0.00443333156 0.0072" />
            <geom mesh="arm#3:base_0" material="arm#3:black" class="visual" />
            <geom mesh="arm#3:base_1" material="arm#3:jointgray" class="visual" />
            <body name="arm#3:shoulder_link" pos="0 0 0.163">
                <inertial mass="3.7" pos="0 0 0" diaginertia="0.0102675 0.0102675 0.00666" />
                <joint name="arm#3:shoulder_pan_joint" class="size3" axis="0 0 1" />
                <geom mesh="arm#3:shoulder_0" material="arm#3:urblue" class="visual" />
                <geom mesh="arm#3:shoulder_1" material="arm#3:black" class="visual" />
                <geom mesh="arm#3:shoulder_2" material="arm#3:jointgray" class="visual" />
                <geom class="collision" size="0.06 0.06" pos="0 0 -0.04" />
                <body name="arm#3:upper_arm_link" pos="0 0.138 0" quat="1 0 1 0">
                    <inertial mass="8.393" pos="0 0 0.2125" diaginertia="0.133886 0.133886 0.0151074" />
                    <joint name="arm#3:shoulder_lift_joint" class="size3" />
                    <geom mesh="arm#3:upperarm_0" material="arm#3:linkgray" class="visual" />
                    <geom mesh="arm#3:upperarm_1" material="arm#3:black" class="visual" />
                    <geom mesh="arm#3:upperarm_2" material="arm#3:jointgray" class="visual" />
                    <geom mesh="arm#3:upperarm_3" material="arm#3:urblue" class="visual" />
                    <geom class="collision" pos="0 -0.04 0" quat="1 1 0 0" size="0.06 0.06" />
                    <geom class="collision" size="0.05 0.2" pos="0 0 0.2" />
                    <body name="arm#3:forearm_link" pos="0 -0.131 0.425">
                        <inertial mass="2.275" pos="0 0 0.196" diaginertia="0.0311796 0.0311796 0.004095" />
                        <joint name="arm#3:elbow_joint" class="size3_limited" />
                        <geom mesh="arm#3:forearm_0" material="arm#3:urblue" class="visual" />
                        <geom mesh="arm#3:forearm_1" material="arm#3:linkgray" class="visual" />
                        <geom mesh="arm#3:forearm_2" material="arm#3:black" class="visual" />
                        <geom mesh="arm#3:forearm_3" material="arm#3:jointgray" class="visual" />
                        <geom class="collision" pos="0 0.08 0" quat="1 1 0 0" size="0.055 0.06" />
                        <geom class="collision" size="0.038 0.19" pos="0 0 0.2" />
                        <body name="arm#3:wrist_1_link" pos="0 0 0.392" quat="1 0 1 0">
                            <inertial mass="1.219" pos="0 0.127 0" diaginertia="0.0025599 0.0025599 0.0021942" />
                            <joint name="arm#3:wrist_1_joint" class="size1" />
                            <geom mesh="arm#3:wrist1_0" material="arm#3:black" class="visual" />
                            <geom mesh="arm#3:wrist1_1" material="arm#3:urblue" class="visual" />
                            <geom mesh="arm#3:wrist1_2" material="arm#3:jointgray" class="visual" />
                            <geom class="collision" pos="0 0.05 0" quat="1 1 0 0" size="0.04 0.07" />
                            <body name="arm#3:wrist_2_link" pos="0 0.127 0">
                                <inertial mass="1.219" pos="0 0 0.1" diaginertia="0.0025599 0.0025599 0.0021942" />
                                <joint name="arm#3:wrist_2_joint" axis="0 0 1" class="size1" />
                                <geom mesh="arm#3:wrist2_0" material="arm#3:black" class="visual" />
                                <geom mesh="arm#3:wrist2_1" material="arm#3:urblue" class="visual" />
                                <geom mesh="arm#3:wrist2_2" material="arm#3:jointgray" class="visual" />
                                <geom class="collision" size="0.04 0.06" pos="0 0 0.04" />
                                <geom class="collision" pos="0 0.02 0.1" quat="1 1 0 0" size="0.04 0.04" />
                                <body name="arm#3:wrist_3_link" pos="0 0 0.1">
                                    <inertial mass="0.1889" pos="0 0.0771683 0" quat="1 0 0 1" diaginertia="0.000132134 9.90863e-05 9.90863e-05" />
                                    <joint name="arm#3:wrist_3_joint" class="size1" />
                                    <geom material="arm#3:linkgray" mesh="arm#3:wrist3" class="visual" />
                                    <geom class="eef_collision" pos="0 0.08 0" quat="1 1 0 0" size="0.04 0.02" />
                                    <site name="arm#3:attachment_site" pos="0 0.1 0" quat="-1 1 0 0" />
                                    <body name="arm#3:ee_link" zaxis="0 1 0" pos="0 0.092 0"><body name="gripper#4:base_mount" pos="0 0 0.007" childclass="2f85">
      <geom class="2f85:visual" mesh="gripper#4:base_mount" material="gripper#4:black" />
      <geom class="2f85:collision" mesh="gripper#4:base_mount" />
      <body name="gripper#4:base" pos="0 0 0.0038" quat="1 0 0 -1">
        <inertial mass="0.777441" pos="0 -2.70394e-05 0.0354675" quat="1 -0.00152849 0 0" diaginertia="0.000260285 0.000225381 0.000152708" />
        <geom class="2f85:visual" mesh="gripper#4:base" material="gripper#4:black" />
        <geom class="2f85:collision" mesh="gripper#4:base" />
        
        <body name="gripper#4:right_driver" pos="0 0.0306011 0.054904">
          <inertial mass="0.00899563" pos="2.96931e-12 0.0177547 0.00107314" quat="0.681301 0.732003 0 0" diaginertia="1.72352e-06 1.60906e-06 3.22006e-07" />
          <joint name="gripper#4:right_driver_joint" class="driver" />
          <geom class="2f85:visual" mesh="gripper#4:driver" material="gripper#4:gray" />
          <geom class="2f85:collision" mesh="gripper#4:driver" />
          <body name="gripper#4:right_coupler" pos="0 0.0315 -0.0041">
            <inertial mass="0.0140974" pos="0 0.00301209 0.0232175" quat="0.705636 -0.0455904 0.0455904 0.705636" diaginertia="4.16206e-06 3.52216e-06 8.88131e-07" />
            <joint name="gripper#4:right_coupler_joint" class="coupler" />
            <geom class="2f85:visual" mesh="gripper#4:coupler" material="gripper#4:black" />
            <geom class="2f85:collision" mesh="gripper#4:coupler" />
          </body>
        </body>
        <body name="gripper#4:right_spring_link" pos="0 0.0132 0.0609">
          <inertial mass="0.0221642" pos="-8.65005e-09 0.0181624 0.0212658" quat="0.663403 -0.244737 0.244737 0.663403" diaginertia="8.96853e-06 6.71733e-06 2.63931e-06" />
          <joint name="gripper#4:right_spring_link_joint" class="spring_link" />
          <geom class="2f85:visual" mesh="gripper#4:spring_link" material="gripper#4:black" />
          <geom class="2f85:collision" mesh="gripper#4:spring_link" />
          <body name="gripper#4:right_follower" pos="0 0.055 0.0375">
            <inertial mass="0.0125222" pos="0 -0.011046 0.0124786" quat="1 0.1664 0 0" diaginertia="2.67415e-06 2.4559e-06 6.02031e-07" />
            <joint name="gripper#4:right_follower_joint" class="follower" />
            <geom class="2f85:visual" mesh="gripper#4:follower_trimmed" material="gripper#4:black" />
            <geom class="2f85:collision" mesh="gripper#4:follower_trimmed" />
            <body name="gripper#4:right_tip"><body xyaxes="0 0 -1 1 0 0" pos="-0.001  0.009 .064">
                            <body name="digit1#5:digit_sensor" pos="0 0 0">

            
            
            <geom name="digit1#5:digit0:back" type="mesh" euler="3.1416 0 1.5708" pos="0.028 0.015 0.036" material="digit1#5:black_resin" mesh="digit1#5:digit_back" mass="0.05" friction="1 0.05 0.01" solimp="1.1 1.2 0.001 0.5 2" solref="0.02 1" />
            <geom name="digit1#5:digit0:adapter" type="mesh" euler="0 -1.5708 3.1416" pos="0.05 0.0097 0.0326" material="digit1#5:silver" mesh="digit1#5:digit_adapter" mass="0.05" friction="1 0.05 0.01" solimp="1.1 1.2 0.001 0.5 2" solref="0.02 1" />
            
            <geom name="digit1#5:digit0:glass" type="mesh" material="digit1#5:transparent_glass" mesh="digit1#5:digit_glass" mass="0.005" contype="0" conaffinity="0" pos="0.024 -0.0085 0.017" euler="0 0 1.5708" />

            
            <geom name="digit1#5:digit0:elastomer" type="mesh" mesh="digit1#5:digit_gel" pos="0.024 -0.0085 0.032" euler="0 0 1.5708" contype="0" conaffinity="0" rgba="0.9 0.95 1 0.0" />

            
            
            <geom name="digit1#5:digit0:elastCover" type="mesh" mesh="digit1#5:digit_curve" pos="0.024 -0.0083 0.0305" euler="0 0 1.5708" contype="0" conaffinity="0" material="digit1#5:silver" friction="1 0.05 0.01" solimp="1.1 1.2 0.001 0.5 2" solref="0.02 1" />

            
            <camera name="digit1#5:digit0:camera" mode="fixed" pos="0.0129 0.0014 0.008" euler="0 3.14159 1.5708" fovy="30" />
            

            
            <geom name="digit1#5:digit0:friction" type="box" size="0.013 0.013 0.00001" euler="0 0 0" pos="0.012 0.001 0.0362" contype="32" conaffinity="32" rgba="0 0 1 0" friction="1 0.05 0.01" solimp="1.1 1.2 0.001 0.5 2" solref="0.02 1" />

        </body>
    </body>
                        </body>
          </body>
        </body>
        
        <body name="gripper#4:left_driver" pos="0 -0.0306011 0.054904" quat="0 0 0 1">
          <inertial mass="0.00899563" pos="0 0.0177547 0.00107314" quat="0.681301 0.732003 0 0" diaginertia="1.72352e-06 1.60906e-06 3.22006e-07" />
          <joint name="gripper#4:left_driver_joint" class="driver" />
          <geom class="2f85:visual" mesh="gripper#4:driver" material="gripper#4:gray" />
          <geom class="2f85:collision" mesh="gripper#4:driver" />
          <body name="gripper#4:left_coupler" pos="0 0.0315 -0.0041">
            <inertial mass="0.0140974" pos="0 0.00301209 0.0232175" quat="0.705636 -0.0455904 0.0455904 0.705636" diaginertia="4.16206e-06 3.52216e-06 8.88131e-07" />
            <joint name="gripper#4:left_coupler_joint" class="coupler" />
            <geom class="2f85:visual" mesh="gripper#4:coupler" material="gripper#4:black" />
            <geom class="2f85:collision" mesh="gripper#4:coupler" />
          </body>
        </body>
        <body name="gripper#4:left_spring_link" pos="0 -0.0132 0.0609" quat="0 0 0 1">
          <inertial mass="0.0221642" pos="-8.65005e-09 0.0181624 0.0212658" quat="0.663403 -0.244737 0.244737 0.663403" diaginertia="8.96853e-06 6.71733e-06 2.63931e-06" />
          <joint name="gripper#4:left_spring_link_joint" class="spring_link" />
          <geom class="2f85:visual" mesh="gripper#4:spring_link" material="gripper#4:black" />
          <geom class="2f85:collision" mesh="gripper#4:spring_link" />
          <body name="gripper#4:left_follower" pos="0 0.055 0.0375">
            <inertial mass="0.0125222" pos="0 -0.011046 0.0124786" quat="1 0.1664 0 0" diaginertia="2.67415e-06 2.4559e-06 6.02031e-07" />
            <joint name="gripper#4:left_follower_joint" class="follower" />
            <geom class="2f85:visual" mesh="gripper#4:follower_trimmed" material="gripper#4:black" />
            <geom class="2f85:collision" mesh="gripper#4:follower_trimmed" />
            <body name="gripper#4:left_tip"><body xyaxes="0 0 -1 1 0 0" pos="-0.001  0.009 .064">
                            <body name="digit2#6:digit_sensor" pos="0 0 0">

            
            
            <geom name="digit2#6:digit0:back" type="mesh" euler="3.1416 0 1.5708" pos="0.028 0.015 0.036" material="digit2#6:black_resin" mesh="digit2#6:digit_back" mass="0.05" friction="1 0.05 0.01" solimp="1.1 1.2 0.001 0.5 2" solref="0.02 1" />
            <geom name="digit2#6:digit0:adapter" type="mesh" euler="0 -1.5708 3.1416" pos="0.05 0.0097 0.0326" material="digit2#6:silver" mesh="digit2#6:digit_adapter" mass="0.05" friction="1 0.05 0.01" solimp="1.1 1.2 0.001 0.5 2" solref="0.02 1" />
            
            <geom name="digit2#6:digit0:glass" type="mesh" material="digit2#6:transparent_glass" mesh="digit2#6:digit_glass" mass="0.005" contype="0" conaffinity="0" pos="0.024 -0.0085 0.017" euler="0 0 1.5708" />

            
            <geom name="digit2#6:digit0:elastomer" type="mesh" mesh="digit2#6:digit_gel" pos="0.024 -0.0085 0.032" euler="0 0 1.5708" contype="0" conaffinity="0" rgba="0.9 0.95 1 0.0" />

            
            
            <geom name="digit2#6:digit0:elastCover" type="mesh" mesh="digit2#6:digit_curve" pos="0.024 -0.0083 0.0305" euler="0 0 1.5708" contype="0" conaffinity="0" material="digit2#6:silver" friction="1 0.05 0.01" solimp="1.1 1.2 0.001 0.5 2" solref="0.02 1" />

            
            <camera name="digit2#6:digit0:camera" mode="fixed" pos="0.0129 0.0014 0.008" euler="0 3.14159 1.5708" fovy="30" />
            

            
            <geom name="digit2#6:digit0:friction" type="box" size="0.013 0.013 0.00001" euler="0 0 0" pos="0.012 0.001 0.0362" contype="32" conaffinity="32" rgba="0 0 1 0" friction="1 0.05 0.01" solimp="1.1 1.2 0.001 0.5 2" solref="0.02 1" />

        </body>
    </body>
                    </body>
          </body>
        </body>
      </body>
    </body>
  </body>
                                </body>
                            </body>
                        </body>
                    </body>
                </body>
            </body>
        </body>
    </worldbody>

        <sensor>
        <actuatorpos name="arm#3:shoulder_pan_pos_sensor" actuator="arm#3:shoulder_pan" />
        <actuatorpos name="arm#3:shoulder_lift_pos_sensor" actuator="arm#3:shoulder_lift" />
        <actuatorpos name="arm#3:elbow_pos_sensor" actuator="arm#3:elbow" />
        <actuatorpos name="arm#3:wrist_1_pos_sensor" actuator="arm#3:wrist_1" />
        <actuatorpos name="arm#3:wrist_2_pos_sensor" actuator="arm#3:wrist_2" />
        <actuatorpos name="arm#3:wrist_3_pos_sensor" actuator="arm#3:wrist_3" />
    <actuatorpos name="gripper#4:fingers_sensor" actuator="gripper#4:fingers_actuator" />
  </sensor>

    <actuator>
        <position class="size3" name="arm#3:shoulder_pan" joint="arm#3:shoulder_pan_joint" />
        <position class="size3" name="arm#3:shoulder_lift" joint="arm#3:shoulder_lift_joint" />
        <position class="size3_limited" name="arm#3:elbow" joint="arm#3:elbow_joint" />
        <position class="size1" name="arm#3:wrist_1" joint="arm#3:wrist_1_joint" />
        <position class="size1" name="arm#3:wrist_2" joint="arm#3:wrist_2_joint" />
        <position class="size1" name="arm#3:wrist_3" joint="arm#3:wrist_3_joint" />
    <general class="2f85" name="gripper#4:fingers_actuator" tendon="gripper#4:split" forcerange="-5 5" ctrlrange="0 255" gainprm="0.3137255 0 0" biasprm="0 -100 -10" />
  </actuator>

    <tendon>
    <fixed name="gripper#4:split">
      <joint joint="gripper#4:right_driver_joint" coef="0.5" />
      <joint joint="gripper#4:left_driver_joint" coef="0.5" />
    </fixed>
  </tendon>

  <equality>
    <connect anchor="0 0 0" body1="gripper#4:right_follower" body2="gripper#4:right_coupler" solimp="0.95 0.99 0.001" solref="0.005 1" />
    <connect anchor="0 0 0" body1="gripper#4:left_follower" body2="gripper#4:left_coupler" solimp="0.95 0.99 0.001" solref="0.005 1" />
    <joint joint1="gripper#4:right_driver_joint" joint2="gripper#4:left_driver_joint" polycoef="0 1 0 0 0" solimp="0.95 0.99 0.001" solref="0.005 1" />
  </equality>

  
  <contact>
    <exclude body1="gripper#4:base" body2="gripper#4:left_driver" />
    <exclude body1="gripper#4:base" body2="gripper#4:right_driver" />
    <exclude body1="gripper#4:base" body2="gripper#4:left_spring_link" />
    <exclude body1="gripper#4:base" body2="gripper#4:right_spring_link" />
    <exclude body1="gripper#4:right_coupler" body2="gripper#4:right_follower" />
    <exclude body1="gripper#4:left_coupler" body2="gripper#4:left_follower" />
  </contact>

  
  </mujoco>