<mujoco>
                    <asset>
        <material name="ur5e#2:black" specular="0.5" shininess="0.25" rgba="0.033 0.033 0.033 1" />
        <material name="ur5e#2:jointgray" specular="0.5" shininess="0.25" rgba="0.278 0.278 0.278 1" />
        <material name="ur5e#2:linkgray" specular="0.5" shininess="0.25" rgba="0.82 0.82 0.82 1" />
        <material name="ur5e#2:urblue" specular="0.5" shininess="0.25" rgba="0.49 0.678 0.8 1" />

        <mesh name="ur5e#2:base_0" file="/home/danfergo/yarok/yarok/comm/components/ur5e/assets/base_0.obj" />
        <mesh name="ur5e#2:base_1" file="/home/danfergo/yarok/yarok/comm/components/ur5e/assets/base_1.obj" />
        <mesh name="ur5e#2:shoulder_0" file="/home/danfergo/yarok/yarok/comm/components/ur5e/assets/shoulder_0.obj" />
        <mesh name="ur5e#2:shoulder_1" file="/home/danfergo/yarok/yarok/comm/components/ur5e/assets/shoulder_1.obj" />
        <mesh name="ur5e#2:shoulder_2" file="/home/danfergo/yarok/yarok/comm/components/ur5e/assets/shoulder_2.obj" />
        <mesh name="ur5e#2:upperarm_0" file="/home/danfergo/yarok/yarok/comm/components/ur5e/assets/upperarm_0.obj" />
        <mesh name="ur5e#2:upperarm_1" file="/home/danfergo/yarok/yarok/comm/components/ur5e/assets/upperarm_1.obj" />
        <mesh name="ur5e#2:upperarm_2" file="/home/danfergo/yarok/yarok/comm/components/ur5e/assets/upperarm_2.obj" />
        <mesh name="ur5e#2:upperarm_3" file="/home/danfergo/yarok/yarok/comm/components/ur5e/assets/upperarm_3.obj" />
        <mesh name="ur5e#2:forearm_0" file="/home/danfergo/yarok/yarok/comm/components/ur5e/assets/forearm_0.obj" />
        <mesh name="ur5e#2:forearm_1" file="/home/danfergo/yarok/yarok/comm/components/ur5e/assets/forearm_1.obj" />
        <mesh name="ur5e#2:forearm_2" file="/home/danfergo/yarok/yarok/comm/components/ur5e/assets/forearm_2.obj" />
        <mesh name="ur5e#2:forearm_3" file="/home/danfergo/yarok/yarok/comm/components/ur5e/assets/forearm_3.obj" />
        <mesh name="ur5e#2:wrist1_0" file="/home/danfergo/yarok/yarok/comm/components/ur5e/assets/wrist1_0.obj" />
        <mesh name="ur5e#2:wrist1_1" file="/home/danfergo/yarok/yarok/comm/components/ur5e/assets/wrist1_1.obj" />
        <mesh name="ur5e#2:wrist1_2" file="/home/danfergo/yarok/yarok/comm/components/ur5e/assets/wrist1_2.obj" />
        <mesh name="ur5e#2:wrist2_0" file="/home/danfergo/yarok/yarok/comm/components/ur5e/assets/wrist2_0.obj" />
        <mesh name="ur5e#2:wrist2_1" file="/home/danfergo/yarok/yarok/comm/components/ur5e/assets/wrist2_1.obj" />
        <mesh name="ur5e#2:wrist2_2" file="/home/danfergo/yarok/yarok/comm/components/ur5e/assets/wrist2_2.obj" />
        <mesh name="ur5e#2:wrist3" file="/home/danfergo/yarok/yarok/comm/components/ur5e/assets/wrist3.obj" />
    </asset>

    <default>
        
        

        <default class="visual">
            <geom type="mesh" contype="0" conaffinity="0" group="2" />
        </default>
        <default class="collision">
            <geom type="capsule" group="3" />
            <default class="eef_collision">
                <geom type="cylinder" />
            </default>
        </default>
        <site size="0.001" rgba="0.5 0.5 0.5 0.3" group="4" />

        
        <default class="size3">
            <joint axis="0 1 0" range="-6.28319 6.28319" armature="0.1" damping="200" />
            <position ctrlrange="-6.2831 6.2831" kp="3500" forcerange="-150 150" />
            <default class="size3_limited">
                <joint range="-3.1415 3.1415" />
                <position ctrlrange="-3.1415 3.1415" />
            </default>
        </default>
        <default class="size1">
            <joint axis="0 1 0" range="-6.28319 6.28319" armature="0.1" damping="15" />
            <position ctrlrange="-6.2831 6.2831" kp="3000" forcerange="-28 28" />
        </default>
    </default>

    <compiler angle="radian" meshdir="assets" autolimits="true" />

                    <worldbody>
                           <body name="ur5e#2:base" quat="1 0 0 1">
            <inertial mass="4.0" pos="0 0 0" diaginertia="0.00443333156 0.00443333156 0.0072" />
            <geom mesh="ur5e#2:base_0" material="ur5e#2:black" class="visual" />
            <geom mesh="ur5e#2:base_1" material="ur5e#2:jointgray" class="visual" />
            <body name="ur5e#2:shoulder_link" pos="0 0 0.163">
                <inertial mass="3.7" pos="0 0 0" diaginertia="0.0102675 0.0102675 0.00666" />
                <joint name="ur5e#2:shoulder_pan_joint" class="size3" axis="0 0 1" />
                <geom mesh="ur5e#2:shoulder_0" material="ur5e#2:urblue" class="visual" />
                <geom mesh="ur5e#2:shoulder_1" material="ur5e#2:black" class="visual" />
                <geom mesh="ur5e#2:shoulder_2" material="ur5e#2:jointgray" class="visual" />
                <geom class="collision" size="0.06 0.06" pos="0 0 -0.04" />
                <body name="ur5e#2:upper_arm_link" pos="0 0.138 0" quat="1 0 1 0">
                    <inertial mass="8.393" pos="0 0 0.2125" diaginertia="0.133886 0.133886 0.0151074" />
                    <joint name="ur5e#2:shoulder_lift_joint" class="size3" />
                    <geom mesh="ur5e#2:upperarm_0" material="ur5e#2:linkgray" class="visual" />
                    <geom mesh="ur5e#2:upperarm_1" material="ur5e#2:black" class="visual" />
                    <geom mesh="ur5e#2:upperarm_2" material="ur5e#2:jointgray" class="visual" />
                    <geom mesh="ur5e#2:upperarm_3" material="ur5e#2:urblue" class="visual" />
                    <geom class="collision" pos="0 -0.04 0" quat="1 1 0 0" size="0.06 0.06" />
                    <geom class="collision" size="0.05 0.2" pos="0 0 0.2" />
                    <body name="ur5e#2:forearm_link" pos="0 -0.131 0.425">
                        <inertial mass="2.275" pos="0 0 0.196" diaginertia="0.0311796 0.0311796 0.004095" />
                        <joint name="ur5e#2:elbow_joint" class="size3_limited" />
                        <geom mesh="ur5e#2:forearm_0" material="ur5e#2:urblue" class="visual" />
                        <geom mesh="ur5e#2:forearm_1" material="ur5e#2:linkgray" class="visual" />
                        <geom mesh="ur5e#2:forearm_2" material="ur5e#2:black" class="visual" />
                        <geom mesh="ur5e#2:forearm_3" material="ur5e#2:jointgray" class="visual" />
                        <geom class="collision" pos="0 0.08 0" quat="1 1 0 0" size="0.055 0.06" />
                        <geom class="collision" size="0.038 0.19" pos="0 0 0.2" />
                        <body name="ur5e#2:wrist_1_link" pos="0 0 0.392" quat="1 0 1 0">
                            <inertial mass="1.219" pos="0 0.127 0" diaginertia="0.0025599 0.0025599 0.0021942" />
                            <joint name="ur5e#2:wrist_1_joint" class="size1" />
                            <geom mesh="ur5e#2:wrist1_0" material="ur5e#2:black" class="visual" />
                            <geom mesh="ur5e#2:wrist1_1" material="ur5e#2:urblue" class="visual" />
                            <geom mesh="ur5e#2:wrist1_2" material="ur5e#2:jointgray" class="visual" />
                            <geom class="collision" pos="0 0.05 0" quat="1 1 0 0" size="0.04 0.07" />
                            <body name="ur5e#2:wrist_2_link" pos="0 0.127 0">
                                <inertial mass="1.219" pos="0 0 0.1" diaginertia="0.0025599 0.0025599 0.0021942" />
                                <joint name="ur5e#2:wrist_2_joint" axis="0 0 1" class="size1" />
                                <geom mesh="ur5e#2:wrist2_0" material="ur5e#2:black" class="visual" />
                                <geom mesh="ur5e#2:wrist2_1" material="ur5e#2:urblue" class="visual" />
                                <geom mesh="ur5e#2:wrist2_2" material="ur5e#2:jointgray" class="visual" />
                                <geom class="collision" size="0.04 0.06" pos="0 0 0.04" />
                                <geom class="collision" pos="0 0.02 0.1" quat="1 1 0 0" size="0.04 0.04" />
                                <body name="ur5e#2:wrist_3_link" pos="0 0 0.1">
                                    <inertial mass="0.1889" pos="0 0.0771683 0" quat="1 0 0 1" diaginertia="0.000132134 9.90863e-05 9.90863e-05" />
                                    <joint name="ur5e#2:wrist_3_joint" class="size1" />
                                    <geom material="ur5e#2:linkgray" mesh="ur5e#2:wrist3" class="visual" />
                                    <geom class="eef_collision" pos="0 0.08 0" quat="1 1 0 0" size="0.04 0.02" />
                                    <site name="ur5e#2:attachment_site" pos="0 0.1 0" quat="-1 1 0 0" />
                                    <body name="ur5e#2:ee_link" zaxis="0 1 0" pos="0 0.092 0" />
                                </body>
                            </body>
                        </body>
                    </body>
                </body>
            </body>
        </body>
    </worldbody>
                <sensor>
        <actuatorpos name="ur5e#2:shoulder_pan_pos_sensor" actuator="ur5e#2:shoulder_pan" />
        <actuatorpos name="ur5e#2:shoulder_lift_pos_sensor" actuator="ur5e#2:shoulder_lift" />
        <actuatorpos name="ur5e#2:elbow_pos_sensor" actuator="ur5e#2:elbow" />
        <actuatorpos name="ur5e#2:wrist_1_pos_sensor" actuator="ur5e#2:wrist_1" />
        <actuatorpos name="ur5e#2:wrist_2_pos_sensor" actuator="ur5e#2:wrist_2" />
        <actuatorpos name="ur5e#2:wrist_3_pos_sensor" actuator="ur5e#2:wrist_3" />
    </sensor>

    <actuator>
        <position class="size3" name="ur5e#2:shoulder_pan" joint="ur5e#2:shoulder_pan_joint" />
        <position class="size3" name="ur5e#2:shoulder_lift" joint="ur5e#2:shoulder_lift_joint" />
        <position class="size3_limited" name="ur5e#2:elbow" joint="ur5e#2:elbow_joint" />
        <position class="size1" name="ur5e#2:wrist_1" joint="ur5e#2:wrist_1_joint" />
        <position class="size1" name="ur5e#2:wrist_2" joint="ur5e#2:wrist_2_joint" />
        <position class="size1" name="ur5e#2:wrist_3" joint="ur5e#2:wrist_3_joint" />
    </actuator>

    </mujoco>